<mujoco model="aloha">
  <compiler angle="radian" meshdir="mehshes" autolimits="true"/>

  <actuator>
    <motor ctrllimited="true" ctrlrange="-35 35" name="left_waist" joint="left_waist"/>
    <motor ctrllimited="true" ctrlrange="-144 144" name="left_shoulder" joint="left_shoulder"/>
    <motor ctrllimited="true" ctrlrange="-59 59" name="left_elbow" joint="left_elbow"/>
    <motor ctrllimited="true" ctrlrange="-22 22" name="left_forearm_roll" joint="left_forearm_roll"/>
    <motor ctrllimited="true" ctrlrange="-35 35" name="left_wrist_angle" joint="left_wrist_angle"/>
    <motor ctrllimited="true" ctrlrange="-35 35" name="left_wrist_rotate" joint="left_wrist_rotate"/>
    <!-- <motor ctrllimited="true" ctrlrange="-35 35" name="left_gripper" joint="left_left_finger"/> -->

    <motor ctrllimited="true" ctrlrange="-35 35" name="right_waist" joint="right_waist"/>
    <motor ctrllimited="true" ctrlrange="-144 144" name="right_shoulder" joint="right_shoulder"/>
    <motor ctrllimited="true" ctrlrange="-59 59" name="right_elbow" joint="right_elbow"/>
    <motor ctrllimited="true" ctrlrange="-22 22" name="right_forearm_roll" joint="right_forearm_roll"/>
    <motor ctrllimited="true" ctrlrange="-35 35" name="right_wrist_angle" joint="right_wrist_angle"/>
    <motor ctrllimited="true" ctrlrange="-35 35" name="right_wrist_rotate" joint="right_wrist_rotate"/>
    <!-- <motor ctrllimited="true" ctrlrange="-35 35" name="right_gripper" joint="right_left_finger"/> -->
  </actuator>

  <option cone="elliptic" impratio="10"/>

  <asset>
    <material name="black" rgba="0.15 0.15 0.15 1"/>

    <mesh name="vx300s_1_base" file="meshes/vx300s_1_base.stl" scale="0.001 0.001 0.001"/>
    <mesh name="vx300s_2_shoulder" file="meshes/vx300s_2_shoulder.stl" scale="0.001 0.001 0.001"/>
    <mesh name="vx300s_3_upper_arm" file="meshes/vx300s_3_upper_arm.stl" scale="0.001 0.001 0.001"/>
    <mesh name="vx300s_4_upper_forearm" file="meshes/vx300s_4_upper_forearm.stl" scale="0.001 0.001 0.001"/>
    <mesh name="vx300s_5_lower_forearm" file="meshes/vx300s_5_lower_forearm.stl" scale="0.001 0.001 0.001"/>
    <mesh name="vx300s_6_wrist" file="meshes/vx300s_6_wrist.stl" scale="0.001 0.001 0.001"/>
  </asset>

  <default>
    <default class="visual">
      <!-- <joint axis="0 1 0" actuatorfrcrange="-35 35"/> -->
      <geom type="mesh" contype="0" conaffinity="0" density="0" group="1" material="black"/>
      <site group="1"/>
    </default>

    <default class="collision">
      <!-- <joint axis="0 1 0" actuatorfrcrange="-35 35"/> -->
      <geom group="0" type="mesh"/>
      <site group="0"/>
    </default>

    <default class="finger_collision">
      <geom group="0" type="mesh" condim="4" solimp="2 1 0.01" solref="0.01 1" friction="1 0.005 0.0001"/>
      <site group="0"/>
    </default>

    <default class="sphere_collision">
      <geom group="0" type="sphere" size="0.0006" rgba="1 0 0 1"/>
      <site group="0"/>
    </default>
  </default>

  <worldbody>
  <body name="base" pos="0 0 0" quat="0.707107 0 0 0.707107">  <!-- is rotating the base okay? -->
    <!-- robot view -->
    <camera mode="fixed" name="robotview" pos="1.0 0 0.4" quat="0.653 0.271 0.271 0.653"/>
    <inertial diaginertia="0 0 0" mass="0" pos="0 0 0"/>
    <!-- mount attached here -->

    <!-- <light mode="targetbodycom" target="left_gripper_link" pos="-.5 .7 2.5" cutoff="55"/> -->
    <!-- <light mode="targetbodycom" target="right_gripper_link" pos=".5 .7 2.5" cutoff="55"/> -->
    
    <camera name="teleoperator_pov" pos="0 -1.354 0.685" xyaxes="1 0 0 0 0.2 .8"/>
    <camera name="collaborator_pov" pos="0 1.5 0.8" xyaxes="-1 0 0 0 -0.2 .8"/>

    <body name="left_base_link"  pos="-0.469 -0.019 0.02" >
      <inertial pos="-0.0534774 -0.000562575 0.0205961" quat="-0.00292324 0.712517 0.00480387 0.701633" mass="0.969034"
        diaginertia="0.0071633 0.00602451 0.00169819"/>
      <geom quat="1 0 0 1" class="visual" mesh="vx300s_1_base"/>
      <geom quat="1 0 0 1" mesh="vx300s_1_base" class="collision"/>
      <body name="left_shoulder_link" pos="0 0 0.079">
        <inertial pos="0.000259233 -3.3552e-06 0.0116129" quat="-0.476119 0.476083 0.52279 0.522826" mass="0.798614"
          diaginertia="0.00120156 0.00113744 0.0009388"/>
        <joint name="left_waist" axis="0 0 1" range="-3.14158 3.14158" damping="5.76" actuatorfrcrange="-35 35"/>
        <geom pos="0 0 -0.003" quat="1 0 0 1" class="visual" mesh="vx300s_2_shoulder"/>
        <geom pos="0 0 -0.003" quat="1 0 0 1" mesh="vx300s_2_shoulder" class="collision"/>
        <body name="left_upper_arm_link" pos="0 0 0.04805">
          <inertial pos="0.0206949 4e-10 0.226459" quat="0 0.0728458 0 0.997343" mass="0.792592"
            diaginertia="0.00911338 0.008925 0.000759317"/>
          <joint name="left_shoulder" axis="0 1 0" range="-1.85005 1.25664" armature="0.395" frictionloss="2.0" damping="20.0" actuatorfrcrange="-144 144"/>
          <geom quat="1 0 0 1" class="visual" mesh="vx300s_3_upper_arm"/>
          <geom quat="1 0 0 1" class="collision" mesh="vx300s_3_upper_arm"/>
          <body name="left_upper_forearm_link" pos="0.05955 0 0.3">
            <inertial pos="0.105723 0 0" quat="-0.000621631 0.704724 0.0105292 0.709403" mass="0.322228"
              diaginertia="0.00144107 0.00134228 0.000152047"/>
            <joint name="left_elbow" axis="0 1 0" range="-1.76278 1.6057" armature="0.383" frictionloss="1.15" damping="18.49" actuatorfrcrange="-59 59"/>
            <geom class="visual" mesh="vx300s_4_upper_forearm"/>
            <geom class="collision" mesh="vx300s_4_upper_forearm"/>
            <body name="left_lower_forearm_link" pos="0.2 0 0">
              <inertial pos="0.0513477 0.00680462 0" quat="-0.702604 -0.0796724 -0.702604 0.0796724" mass="0.414823"
                diaginertia="0.0005911 0.000546493 0.000155707"/>
              <joint name="left_forearm_roll" axis="1 0 0" range="-3.14158 3.14158" armature="0.14" damping="6.78" actuatorfrcrange="-22 22"/>
              <geom quat="0 1 0 0" class="visual" mesh="vx300s_5_lower_forearm"/>
              <geom quat="0 1 0 0" class="collision" mesh="vx300s_5_lower_forearm"/>
              <body name="left_wrist_link" pos="0.1 0 0">
                <inertial pos="0.046743 -7.6652e-06 0.010565" quat="-0.00100191 0.544586 0.0026583 0.8387"
                  mass="0.115395" diaginertia="5.45707e-05 4.63101e-05 4.32692e-05"/>
                <joint name="left_wrist_angle" axis="0 1 0" range="-1.8675 2.23402" armature="0.008" damping="6.28" actuatorfrcrange="-35 35"/>
                <geom quat="1 0 0 1" class="visual" mesh="vx300s_6_wrist"/>
                <geom quat="1 0 0 1" class="collision" mesh="vx300s_6_wrist"/>
                <body name="left_gripper_link" pos="0.069744 0 0">
                  <inertial pos="0.0395662 -2.56311e-07 0.00400649" quat="0.62033 0.619916 -0.339682 0.339869"
                    mass="0.251652" diaginertia="0.000689546 0.000650316 0.000468142"/>
                  <joint name="left_wrist_rotate" axis="1 0 0" range="-3.14158 3.14158" damping="1.2" actuatorfrcrange="-35 35"/>
                  <site name="left_gripper" pos="0.15 0 0" group="0"/>

                  <body name="left_hand" pos="0 0 0" euler="1.57 1.57 -1.57">
                    <!-- This sites were added for visualization. They are all standardized between models-->
                    <!-- Position mimics the gripper attachment point (right_hand) -->
                    <!--  Y-axis should be perpendicular to grasping motion, and Z-axis should point out of the robot eef -->
                    <site name="left_ee" pos="0 0 0" size="0.01 0.01 0.01" rgba="0 0 1 1" type="sphere" group="1"/>
                    <site name="left_ee_x" pos="0 0 0" size="0.005 .1"  quat="0.707105 0.707108 0 0 " rgba="1 0 0 0" type="cylinder" group="1"/>
                    <site name="left_ee_z" pos="0 0 0" size="0.005 .1" quat="0.707105 0 0 0.707108" rgba="0 0 1 0" type="cylinder" group="1"/>
                    <site name="left_ee_y" pos="0 0 0" size="0.005 .1" quat="0.707105 0 0.707108 0 " rgba="0 1 0 0" type="cylinder" group="1"/>
                    <!-- This camera points out from the eef. -->
                    <camera mode="fixed" name="left_eye_in_hand" pos="0.05 0 0" quat="0 0.707108 0.707108 0" fovy="75"/>
                    <!-- to add gripper -->
                  </body>

                </body>
              </body>
            </body>
          </body>
        </body>
      </body>
    </body>

    <body name="right_base_link" pos="0.469 -0.019 0.02" quat="0 0 0 1">
      <inertial pos="-0.0534774 -0.000562575 0.0205961" quat="-0.00292324 0.712517 0.00480387 0.701633" mass="0.969034"
        diaginertia="0.0071633 0.00602451 0.00169819"/>
      <geom quat="1 0 0 1" class="visual" mesh="vx300s_1_base"/>
      <geom quat="1 0 0 1" mesh="vx300s_1_base" class="collision"/>
      <body name="right_shoulder_link" pos="0 0 0.079">
        <inertial pos="0.000259233 -3.3552e-06 0.0116129" quat="-0.476119 0.476083 0.52279 0.522826" mass="0.798614"
          diaginertia="0.00120156 0.00113744 0.0009388"/>
        <joint name="right_waist" axis="0 0 1" range="-3.14158 3.14158" damping="5.76" actuatorfrcrange="-35 35"/>
        <geom pos="0 0 -0.003" quat="1 0 0 1" class="visual" mesh="vx300s_2_shoulder"/>
        <geom pos="0 0 -0.003" quat="1 0 0 1" mesh="vx300s_2_shoulder" class="collision"/>
        <body name="right_upper_arm_link" pos="0 0 0.04805">
          <inertial pos="0.0206949 4e-10 0.226459" quat="0 0.0728458 0 0.997343" mass="0.792592"
            diaginertia="0.00911338 0.008925 0.000759317"/>
          <joint name="right_shoulder" axis="0 1 0" range="-1.85005 1.25664" armature="0.395" frictionloss="2.0" damping="20.0" actuatorfrcrange="-144 144"/>
          <geom quat="1 0 0 1" class="visual" mesh="vx300s_3_upper_arm"/>
          <geom quat="1 0 0 1" class="collision" mesh="vx300s_3_upper_arm"/>
          <body name="right_upper_forearm_link" pos="0.05955 0 0.3">
            <inertial pos="0.105723 0 0" quat="-0.000621631 0.704724 0.0105292 0.709403" mass="0.322228"
              diaginertia="0.00144107 0.00134228 0.000152047"/>
            <joint name="right_elbow" axis="0 1 0" range="-1.76278 1.6057" armature="0.383" frictionloss="1.15" damping="18.49" actuatorfrcrange="-59 59"/>
            <geom class="visual" mesh="vx300s_4_upper_forearm"/>
            <geom class="collision" mesh="vx300s_4_upper_forearm"/>
            <body name="right_lower_forearm_link" pos="0.2 0 0">
              <inertial pos="0.0513477 0.00680462 0" quat="-0.702604 -0.0796724 -0.702604 0.0796724" mass="0.414823"
                diaginertia="0.0005911 0.000546493 0.000155707"/>
              <joint name="right_forearm_roll" axis="1 0 0" range="-3.14158 3.14158" armature="0.14" damping="6.78" actuatorfrcrange="-22 22"/>
              <geom quat="0 1 0 0" class="visual" mesh="vx300s_5_lower_forearm"/>
              <geom quat="0 1 0 0" class="collision" mesh="vx300s_5_lower_forearm"/>
              <body name="right_wrist_link" pos="0.1 0 0">
                <inertial pos="0.046743 -7.6652e-06 0.010565" quat="-0.00100191 0.544586 0.0026583 0.8387"
                  mass="0.115395" diaginertia="5.45707e-05 4.63101e-05 4.32692e-05"/>
                <joint name="right_wrist_angle" axis="0 1 0" range="-1.8675 2.23402" armature="0.008" damping="6.28" actuatorfrcrange="-35 35"/>
                <geom quat="1 0 0 1" class="visual" mesh="vx300s_6_wrist"/>
                <geom quat="1 0 0 1" class="collision" mesh="vx300s_6_wrist"/>
                
                <body name="right_gripper_link" pos="0.069744 0 0">
                  <inertial pos="0.0395662 -2.56311e-07 0.00400649" quat="0.62033 0.619916 -0.339682 0.339869"
                    mass="0.251652" diaginertia="0.000689546 0.000650316 0.000468142"/>
                  <joint name="right_wrist_rotate" axis="1 0 0" range="-3.14158 3.14158" damping="1.2" actuatorfrcrange="-35 35"/>
                  <site name="right_gripper" pos="0.15 0 0" group="0"/>

                  <body name="right_hand" euler="1.57 1.57 -1.57" pos="0 0 0">
                    <!-- This sites were added for visualization. They are all standardized between models-->
                    <!-- Position mimics the gripper attachment point (right_hand) -->
                    <!--  Y-axis should be perpendicular to grasping motion, and Z-axis should point out of the robot eef -->
                    <site name="right_ee" pos="0 0 0" size="0.01 0.01 0.01" rgba="0 0 1 1" type="sphere" group="1"/>
                    <site name="right_ee_x" pos="0 0 0" size="0.005 .1"  quat="0.707105 0.707108 0 0 " rgba="1 0 0 0" type="cylinder" group="1"/>
                    <site name="right_ee_z" pos="0 0 0" size="0.005 .1" quat="0.707105 0 0 0.707108" rgba="0 0 1 0" type="cylinder" group="1"/>
                    <site name="right_ee_y" pos="0 0 0" size="0.005 .1" quat="0.707105 0 0.707108 0 " rgba="0 1 0 0" type="cylinder" group="1"/>
                    <!-- This camera points out from the eef. -->
                    <camera mode="fixed" name="right_eye_in_hand" pos="0.05 0 0" quat="0 0.707108 0.707108 0" fovy="75"/>
                    <!-- to add gripper -->
                  </body>
                  
                </body>
              </body>
            </body>
          </body>
        </body>
      </body>
    </body>
  </body>
  </worldbody>

  <contact>
    <exclude body1="left_base_link" body2="left_shoulder_link"/>
    <exclude body1="right_base_link" body2="right_shoulder_link"/>
  </contact>
</mujoco>
