<mujoco model="aloha_gripper">
  <compiler angle="radian" autolimits="true"/>

  <actuator>
    <position class="left_finger" name="gripper_l_finger_joint" joint="left_finger"/>
    <position class="right_finger" name="gripper_r_finger_joint" joint="right_finger"/>
  </actuator>

  <option cone="elliptic" impratio="10"/>

  <asset>
    <material name="black" rgba="0.15 0.15 0.15 1"/>

    <mesh name="vx300s_7_gripper_prop" file="meshes/aloha_gripper/vx300s_7_gripper_prop.stl"/>
    <mesh name="vx300s_7_gripper_bar" file="meshes/aloha_gripper/vx300s_7_gripper_bar.stl"/>
    <mesh name="vx300s_7_gripper_wrist_mount" file="meshes/aloha_gripper/vx300s_7_gripper_wrist_mount.stl"/>
    <mesh name="vx300s_8_custom_finger_left" file="meshes/aloha_gripper/vx300s_8_custom_finger_left.stl"/>
    <mesh name="vx300s_8_custom_finger_right" file="meshes/aloha_gripper/vx300s_8_custom_finger_right.stl"/>
    <mesh name="d405_solid" file="meshes/aloha_gripper/d405_solid.stl"/>
  </asset>

  <default>
    <default class="visual">
      <geom type="mesh" contype="0" conaffinity="0" density="0" group="1" material="black"/>
      <site group="1"/>
    </default>

    <default class="collision">
      <geom group="0" type="mesh"/>
      <site group="0"/>
    </default>

    <default class="finger_collision">
      <geom group="0" type="mesh" condim="4" solimp="2 1 0.01" solref="0.01 1" friction="1 0.005 0.0001"/>
      <site group="0"/>
    </default>

    <default class="sphere_collision">
      <geom group="0" type="sphere" size="0.0006" rgba="1 0 0 1"/>
      <site group="0"/>
    </default>


    <!--
      The joint and control ranges are in meters, representing the linear displacement of the
      finger on the rail. Note that the real robot takes in a float value representing the
      position of the dynamixel servo, which actuates rotors and moves the fingers along the
      the rail. We choose to model the displacement of the finger on the rail instead of the
      position of the servo because the former is a more interpretable value.

      Some useful values:
      Length of rail = 12cm
      Width of finger base = 1.9cm

      Joint range should be (0.0cm, 4.1cm). This represents the _physical_ limits of the
      fingers sliding along the rail. The 0 position represents when the inner edge of
      the finger bases are touching each other at exactly the center of the rail.
      4.1cm represents the outer edge of the finger bases touching the edge of the rail.
      So the value always represents the distance from the inner edge of the finger base
      to the center of the rail.

      Control range is (0.2cm, 3.7cm). This represents measured values from a real robot
      where the gripper is actuated to its fully closed and fully open positions. Therefore the
      control range represents limits enforced by _software_ on the real robot.
    -->
    <default class="finger">
      <joint type="slide" armature="0.243" damping="40"/>
      <position ctrlrange="0.002 0.037" kp="2000" kv="124"/>
    </default>

    <default class="left_finger">
      <joint type="slide" armature="0.243" damping="40" range="0 0.041" axis="0 0 -1"/>
      <position ctrlrange="0.002 0.037" kp="2000" kv="124"/>
    </default>

    <default class="right_finger">
      <joint type="slide" armature="0.243" damping="40" range="0 0.041" axis="0 0 -1"/>
      <position ctrlrange="0.002 0.037" kp="2000" kv="124"/>
    </default>
  </default>

  <worldbody>
    <body name="gripper_base" pos="0 0 0">

      <site name="ft_frame" pos="0 0 0" size="0.01 0.01 0.01" rgba="1 0 0 1" type="sphere" group="1" />
      
      <body name="eef" pos="0 0 0.035" euler="0 0 -1.57">
        <!-- This site was added for visualization. -->
        <site name="grip_site" pos="0 0 0" size="0.01 0.01 0.01" rgba="1 0 0 0.5" type="sphere" group="1"/>
        <!-- This site was added for visualization. -->
        <site name="grip_site_cylinder" pos="0 0 0.1399" size="0.005 10" rgba="0 1 0 0.3" type="cylinder" group="1"/>


        <inertial pos="0.000182154 -0.0341589 -0.0106026" quat="0.435286 0.557074 -0.551539 0.442718"
          mass="0.42158" diaginertia="0.00110438 0.000790537 0.000469727"/>
        <geom name="gripper_base_prop_vis" class="visual" mesh="vx300s_7_gripper_prop"/>
        <geom name="gripper_base_prop_col" class="collision" mesh="vx300s_7_gripper_prop"/>
        <geom name="gripper_base_bar_vis" class="visual" mesh="vx300s_7_gripper_bar"/>
        <geom name="gripper_base_bar_col" class="collision" mesh="vx300s_7_gripper_bar"/>
        <geom name="gripper_base_wrist_mount_vis" class="visual" pos="0 -0.03525 -0.0227" quat="0 -1 0 -1" type="mesh" mesh="vx300s_7_gripper_wrist_mount"/>
        <geom name="gripper_base_wrist_mount_col" class="collision" pos="0 -0.03525 -0.0227" quat="0 -1 0 -1" type="mesh" mesh="vx300s_7_gripper_wrist_mount"/>
        <geom name="gripper_base_d405_vis" class="visual" pos="0 -0.0824748 -0.0095955" quat="0 0 -0.21644 -0.976296" type="mesh" mesh="d405_solid"/>
        <geom name="gripper_base_d405_col" class="collision" pos="0 -0.0824748 -0.0095955" quat="0 0 -0.21644 -0.976296" type="mesh" mesh="d405_solid"/>
        
        <camera name="wrist_cam" pos="0 -0.0824748 -0.0095955" fovy="58" mode="fixed" euler="2.70525955359 0 0"/>
        <body name="left_finger_link" pos="0.0191 -0.0141637 0.0211727" quat="1 -1 -1 1">
          <inertial pos="0.0143478 -0.0284791 0.0122897" quat="0.535486 0.458766 -0.450407 0.547651"
            mass="0.0862937" diaginertia="5.86848e-05 4.46887e-05 1.8397e-05"/>
          <joint name="left_finger" class="left_finger"/>
          <geom name="l_finger_vis" pos="0.0141637 0.0211727 0.06" class="visual" quat="1 1 1 -1" type="mesh"
            mesh="vx300s_8_custom_finger_left"/>
          <geom name="l_finger_col" pos="0.0141637 0.0211727 0.06" class="finger_collision" quat="1 1 1 -1" type="mesh"
            mesh="vx300s_8_custom_finger_left"/>
          <geom name="l_finger_g0_col" pos="0.013  -0.0892 0.0268" class="sphere_collision"/>
          <geom name="l_finger_g1_col" pos="0.0222 -0.0892 0.0268" class="sphere_collision"/>
          <geom name="l_finger_g2_col" pos="0.0182 -0.0845 0.0266" class="sphere_collision"/>
          <site name="left_finger" pos="0.015 -0.06 0.02"/>
        </body>
        <body name="right_finger_link" pos="-0.0191 -0.0141637 0.0211727" quat="1 1 1 1">
          <inertial pos="0.0143711 0.0284792 0.0121421" quat="0.461317 0.537615 -0.545478 0.447894"
            mass="0.0862932" diaginertia="5.86828e-05 4.46887e-05 1.83949e-05"/>
          <joint name="right_finger" class="right_finger"/>
          <geom name="r_finger_vis" pos="0.0141637 -0.0211727 0.0597067" class="visual" quat="1 -1 -1 -1" type="mesh"
            mesh="vx300s_8_custom_finger_right"/>
          <geom name="r_finger_col" pos="0.0141637 -0.0211727 0.0597067" class="finger_collision" quat="1 -1 -1 -1" type="mesh"
            mesh="vx300s_8_custom_finger_right"/>
          <geom name="r_finger_g0_col" pos="0.013  0.0892 0.0268" class="sphere_collision"/>
          <geom name="r_finger_g1_col" pos="0.0222 0.0892 0.0268" class="sphere_collision"/>
          <geom name="r_finger_g2_col" pos="0.0182 0.0845 0.0266" class="sphere_collision"/>
          <site name="right_finger" pos="0.015 0.06 0.02"/>
        </body>
      </body>
    </body>
  </worldbody>

  <sensor>
    <force name="force_ee" site="ft_frame"/>
    <torque name="torque_ee" site="ft_frame"/>
  </sensor>
</mujoco>
