<mujoco model="rg2">
  <compiler angle="radian" meshdir="/home/jhlee/workspace/rg2_simulation/mj_meshes/"/>
  <asset>
    <mesh name="RG2_Hand_col" file="RG2_Hand_col.STL"/>
    <mesh name="RG2_Hand_vis" file="RG2_Hand_vis.STL"/>
    <mesh name="RG2_LeftMomentArm_col" file="RG2_LeftMomentArm_col.STL"/>
    <mesh name="RG2_LeftMomentArm_vis" file="RG2_LeftMomentArm_vis.STL"/>
    <mesh name="RG2_LeftFinger_col" file="RG2_LeftFinger_col.STL"/>
    <mesh name="RG2_LeftFinger_vis" file="RG2_LeftFinger_vis.STL"/>
    <mesh name="RG2_LeftTrussArm_col" file="RG2_LeftTrussArm_col.STL"/>
    <mesh name="RG2_LeftTrussArm_vis" file="RG2_LeftTrussArm_vis.STL"/>
    <mesh name="RG2_RightMomentArm_col" file="RG2_RightMomentArm_col.STL"/>
    <mesh name="RG2_RightMomentArm_vis" file="RG2_RightMomentArm_vis.STL"/>
    <mesh name="RG2_RightFinger_col" file="RG2_RightFinger_col.STL"/>
    <mesh name="RG2_RightFinger_vis" file="RG2_RightFinger_vis.STL"/>
    <mesh name="RG2_RightTrussArm_col" file="RG2_RightTrussArm_col.STL"/>
    <mesh name="RG2_RightTrussArm_vis" file="RG2_RightTrussArm_vis.STL"/>
  </asset>
  
  <worldbody>
    <geom name="rg2_hand_col" type="mesh" mesh="RG2_Hand_col"/>
    <geom name="rg2_hand_vis" type="mesh" contype="0" conaffinity="0" group="1" density="0" mesh="RG2_Hand_vis"/>
    <body name="l_moment_arm_link" pos="0.105 0.017 0.01">
      <inertial pos="0.017004 0.006397 -0.0103" quat="0.116079 0.697514 -0.116079 0.697514" mass="0.160209" diaginertia="8.3e-05 7.8504e-05 1.6496e-05"/>
      <joint name="gripper_joint" pos="0 0 0" axis="0 0 1" limited="true" range="-0.45 1.5708" damping="0.1"/>
      <geom type="mesh" mesh="RG2_LeftMomentArm_col"/>
      <geom type="mesh" contype="0" conaffinity="0" group="1" density="0" mesh="RG2_LeftMomentArm_vis"/>
      <body name="l_finger_link" pos="0.049 0.026 0">
        <inertial pos="0.024695 -0.010178 -0.010001" quat="0.435925 0.435925 0.556749 0.556749" mass="0.081638" diaginertia="2.62355e-05 2.6e-05 4.76454e-06"/>
        <joint name="l_finger_2_joint" pos="0 0 0" axis="0 0 1" limited="true" range="-1.5708 1.5708" damping="0.1"/>
        <geom type="mesh" mesh="RG2_LeftFinger_col"/>
        <geom type="mesh" contype="0" conaffinity="0" group="1" density="0" mesh="RG2_LeftFinger_vis"/>
      </body>
    </body>
    <body name="l_truss_arm_link" pos="0.122 0.008 0.01">
      <inertial pos="0.023075 0.012136 -0.01" quat="0.604527 0.604527 0.366807 0.366807" mass="0.065927" diaginertia="2.92066e-05 2.5e-05 4.79344e-06"/>
      <joint name="l_finger_passive_joint" pos="0 0 0" axis="0 0 1" limited="true" range="-1.5708 1.5708" damping="0.1"/>
      <geom type="mesh" mesh="RG2_LeftTrussArm_col"/>
      <geom type="mesh" contype="0" conaffinity="0" group="1" density="0" mesh="RG2_LeftTrussArm_vis"/>
    </body>
    <body name="r_moment_arm_link" pos="0.105 -0.017 0.01">
      <inertial pos="0.017004 -0.006397 -0.0103" quat="-0.116079 0.697514 0.116079 0.697514" mass="0.160209" diaginertia="8.3e-05 7.8504e-05 1.6496e-05"/>
      <joint name="r_finger_1_joint" pos="0 0 0" axis="0 0 1" limited="true" range="-1.5708 1.5708" damping="0.1"/>
      <geom type="mesh" mesh="RG2_RightMomentArm_col"/>
      <geom type="mesh" contype="0" conaffinity="0" group="1" density="0" mesh="RG2_RightMomentArm_vis"/>
      <body name="r_finger_link" pos="0.049 -0.026 0">
        <inertial pos="0.024695 0.010178 -0.01" quat="0.556749 0.556749 0.435925 0.435925" mass="0.081637" diaginertia="2.62355e-05 2.6e-05 4.76454e-06"/>
        <joint name="r_finger_2_joint" pos="0 0 0" axis="0 0 1" limited="true" range="-1.5708 1.5708" damping="0.1"/>
        <geom type="mesh" mesh="RG2_RightFinger_col"/>
        <geom type="mesh" contype="0" conaffinity="0" group="1" density="0" mesh="RG2_RightFinger_vis"/>
      </body>
    </body>
    <body name="r_truss_arm_link" pos="0.122 -0.008 0.01">
      <inertial pos="0.023075 -0.012136 -0.01" quat="0.366807 0.366807 0.604527 0.604527" mass="0.065927" diaginertia="2.92066e-05 2.5e-05 4.79344e-06"/>
      <joint name="r_finger_passive_joint" pos="0 0 0" axis="0 0 1" limited="true" range="-1.5708 1.5708" damping="0.1"/>
      <geom type="mesh" mesh="RG2_RightTrussArm_col"/>
      <geom type="mesh" contype="0" conaffinity="0" group="1" density="0" mesh="RG2_RightTrussArm_vis"/>
    </body>
  </worldbody>
</mujoco>
